Workbook

Sheet Summary
A2: Monthly profit and loss summary
A3: Business / project | B3: =Breakdown!B3 -> Cheapify
A4: Year | B4: =Breakdown!B4 -> 2026 | D4: Currency | E4: =Breakdown!E4 -> IQD | G4: Report type | H4: =Breakdown!H4 -> Budget
A5: Linked to the Breakdown sheet. | B5: Blank inputs are treated as zero. Complete every month before using the results.
A6: Category | B6: =Breakdown!B6 -> 46023 | C6: =Breakdown!C6 -> 46054 | D6: =Breakdown!D6 -> 46082 | E6: =Breakdown!E6 -> 46113 | F6: =Breakdown!F6 -> 46143 | G6: =Breakdown!G6 -> 46174 | H6: =Breakdown!H6 -> 46204 | I6: =Breakdown!I6 -> 46235 | ... M6: =Breakdown!M6 -> 46357 | N6: Annual total
A8: Total revenue | B8: =Breakdown!B12 -> 225000 | C8: =Breakdown!C12 -> 525000 | D8: =Breakdown!D12 -> 750000 | E8: =Breakdown!E12 -> 1050000 | F8: =Breakdown!F12 -> 1275000 | G8: =Breakdown!G12 -> 1425000 | H8: =Breakdown!H12 -> 1800000 | I8: =Breakdown!I12 -> 2025000 | ... N8: =Breakdown!N12 -> 21000000
A9: Total COGS | B9: =Breakdown!B19 -> 100000 | C9: =Breakdown!C19 -> 100000 | D9: =Breakdown!D19 -> 100000 | E9: =Breakdown!E19 -> 100000 | F9: =Breakdown!F19 -> 100000 | G9: =Breakdown!G19 -> 100000 | H9: =Breakdown!H19 -> 150000 | I9: =Breakdown!I19 -> 172500 | ... N9: =Breakdown!N19 -> 1905000
A11: Gross profit | B11: =Breakdown!B21 -> 125000 | C11: =Breakdown!C21 -> 425000 | D11: =Breakdown!D21 -> 650000 | E11: =Breakdown!E21 -> 950000 | F11: =Breakdown!F21 -> 1175000 | G11: =Breakdown!G21 -> 1325000 | H11: =Breakdown!H21 -> 1650000 | I11: =Breakdown!I21 -> 1852500 | ... N11: =Breakdown!N21 -> 19095000
A12: Gross profit margin | B12: =Breakdown!B22 -> 0.5556 | C12: =Breakdown!C22 -> 0.8095 | D12: =Breakdown!D22 -> 0.8667 | E12: =Breakdown!E22 -> 0.9048 | F12: =Breakdown!F22 -> 0.9216 | G12: =Breakdown!G22 -> 0.9298 | H12: =Breakdown!H22 -> 0.9167 | I12: =Breakdown!I22 -> 0.9148 | ... N12: =Breakdown!N22 -> 0.9093
A14: Total indirect costs | B14: =Breakdown!B35 -> 450000 | C14: =Breakdown!C35 -> 450000 | D14: =Breakdown!D35 -> 450000 | E14: =Breakdown!E35 -> 450000 | F14: =Breakdown!F35 -> 450000 | G14: =Breakdown!G35 -> 450000 | H14: =Breakdown!H35 -> 234000 | I14: =Breakdown!I35 -> 238500 | ... N14: =Breakdown!N35 -> 4272000
A16: Operating profit / (loss) | B16: =Breakdown!B37 -> -325000 | C16: =Breakdown!C37 -> -25000 | D16: =Breakdown!D37 -> 200000 | E16: =Breakdown!E37 -> 500000 | F16: =Breakdown!F37 -> 725000 | G16: =Breakdown!G37 -> 875000 | H16: =Breakdown!H37 -> 1416000 | I16: =Breakdown!I37 -> 1614000 | ... N16: =Breakdown!N37 -> 14823000
A18: GIZ Seed Grant Disbursement (Pilot Support) | B18: =Breakdown!B40 -> 550000 | C18: =Breakdown!C40 -> 550000 | D18: =Breakdown!D40 -> 550000 | E18: =Breakdown!E40 -> 550000 | F18: =Breakdown!F40 -> 550000 | G18: =Breakdown!G40 -> 550000 | H18: =Breakdown!H40 -> 0 | I18: =Breakdown!I40 -> 0 | ... N18: =Breakdown!N40 -> 3300000
A19: Interest expense | B19: =Breakdown!B41 -> 0 | C19: =Breakdown!C41 -> 0 | D19: =Breakdown!D41 -> 0 | E19: =Breakdown!E41 -> 0 | F19: =Breakdown!F41 -> 0 | G19: =Breakdown!G41 -> 0 | H19: =Breakdown!H41 -> 0 | I19: =Breakdown!I41 -> 0 | ... N19: =Breakdown!N41 -> 0
A20: Profit / (loss) before tax | B20: =Breakdown!B42 -> 225000 | C20: =Breakdown!C42 -> 525000 | D20: =Breakdown!D42 -> 750000 | E20: =Breakdown!E42 -> 1050000 | F20: =Breakdown!F42 -> 1275000 | G20: =Breakdown!G42 -> 1425000 | H20: =Breakdown!H42 -> 1416000 | I20: =Breakdown!I42 -> 1614000 | ... N20: =Breakdown!N42 -> 18123000
A21: Income tax expense | B21: =Breakdown!B43 -> 0 | C21: =Breakdown!C43 -> 0 | D21: =Breakdown!D43 -> 0 | E21: =Breakdown!E43 -> 0 | F21: =Breakdown!F43 -> 0 | G21: =Breakdown!G43 -> 0 | H21: =Breakdown!H43 -> 0 | I21: =Breakdown!I43 -> 0 | ... N21: =Breakdown!N43 -> 0
A23: Net profit / (loss) | B23: =Breakdown!B45 -> 225000 | C23: =Breakdown!C45 -> 525000 | D23: =Breakdown!D45 -> 750000 | E23: =Breakdown!E45 -> 1050000 | F23: =Breakdown!F45 -> 1275000 | G23: =Breakdown!G45 -> 1425000 | H23: =Breakdown!H45 -> 1416000 | I23: =Breakdown!I45 -> 1614000 | ... N23: =Breakdown!N45 -> 18123000
A24: Net profit margin | B24: =Breakdown!B46 -> 1 | C24: =Breakdown!C46 -> 1 | D24: =Breakdown!D46 -> 1 | E24: =Breakdown!E46 -> 1 | F24: =Breakdown!F46 -> 1 | G24: =Breakdown!G46 -> 1 | H24: =Breakdown!H46 -> 0.7867 | I24: =Breakdown!I46 -> 0.797 | ... N24: =Breakdown!N46 -> 0.863

Sheet Breakdown
A2: Monthly profit and loss breakdown
A3: Business / project | B3: Cheapify
A4: Year | B4: 2026 | D4: Currency | E4: IQD | G4: Report type | H4: Budget
A5: Enter amounts in yellow cells. | B5: Rename the product and cost labels as needed. Enter costs and discounts as positive amounts.
A6: Category | B6: =DATE($B$4,1,1) -> 46023 | C6: =DATE($B$4,2,1) -> 46054 | D6: =DATE($B$4,3,1) -> 46082 | E6: =DATE($B$4,4,1) -> 46113 | F6: =DATE($B$4,5,1) -> 46143 | G6: =DATE($B$4,6,1) -> 46174 | H6: =DATE($B$4,7,1) -> 46204 | I6: =DATE($B$4,8,1) -> 46235 | J6: =DATE($B$4,9,1) -> 46266 | K6: =DATE($B$4,10,1) -> 46296 | L6: =DATE($B$4,11,1) -> 46327 | M6: =DATE($B$4,12,1) -> 46357 | N6: Annual total
A7: REVENUE
A8: Transaction Fees (Platform Take-Rate: 1,500 IQD avg) | B8: 225000 | C8: 375000 | D8: 600000 | E8: 900000 | F8: 1125000 | G8: 1275000 | H8: 1500000 | I8: 1725000 | J8: 1950000 | K8: 2250000 | L8: 2625000 | M8: 3000000 | N8: =SUM(B8:M8) -> 17550000
A9: Category & Shop Sponsorships (150,000 IQD / mo) | B9: 0 | C9: 150000 | D9: 150000 | E9: 150000 | F9: 150000 | G9: 150000 | H9: 300000 | I9: 300000 | J9: 450000 | K9: 450000 | L9: 600000 | M9: 600000 | N9: =SUM(B9:M9) -> 3450000
A10: Value-Add Services (Analytics) | B10: 0 | C10: 0 | D10: 0 | E10: 0 | F10: 0 | G10: 0 | H10: 0 | I10: 0 | J10: 0 | K10: 0 | L10: 0 | M10: 0 | N10: =SUM(B10:M10) -> 0
A11: Less: discounts and returns | B11: 0 | C11: 0 | D11: 0 | E11: 0 | F11: 0 | G11: 0 | H11: 0 | I11: 0 | J11: 0 | K11: 0 | L11: 0 | M11: 0 | N11: =SUM(B11:M11) -> 0
A12: Total revenue | B12: =SUM(B8:B10)-B11 -> 225000 | C12: =SUM(C8:C10)-C11 -> 525000 | D12: =SUM(D8:D10)-D11 -> 750000 | E12: =SUM(E8:E10)-E11 -> 1050000 | F12: =SUM(F8:F10)-F11 -> 1275000 | G12: =SUM(G8:G10)-G11 -> 1425000 | H12: =SUM(H8:H10)-H11 -> 1800000 | I12: =SUM(I8:I10)-I11 -> 2025000 | ... M12: =SUM(M8:M10)-M11 -> 3600000 | N12: =SUM(B12:M12) -> 21000000
A14: COST OF GOODS SOLD (COGS)
A15: Materials / merchandise sold | B15: 0 | C15: 0 | D15: 0 | E15: 0 | F15: 0 | G15: 0 | H15: 0 | I15: 0 | J15: 0 | K15: 0 | L15: 0 | M15: 0 | N15: =SUM(B15:M15) -> 0
A16: Direct labor for goods sold | B16: 0 | C16: 0 | D16: 0 | E16: 0 | F16: 0 | G16: 0 | H16: 0 | I16: 0 | J16: 0 | K16: 0 | L16: 0 | M16: 0 | N16: =SUM(B16:M16) -> 0
A17: Branded Packaging Supplies (Tape & Waybills) | B17: 25000 | C17: 25000 | D17: 25000 | E17: 25000 | F17: 25000 | G17: 25000 | H17: 50000 | I17: 57500 | J17: 65000 | K17: 75000 | L17: 87500 | M17: 100000 | N17: =SUM(B17:M17) -> 585000
A18: Payment Gateway Fees & Courier Subsidies | B18: 75000 | C18: 75000 | D18: 75000 | E18: 75000 | F18: 75000 | G18: 75000 | H18: 100000 | I18: 115000 | J18: 130000 | K18: 150000 | L18: 175000 | M18: 200000 | N18: =SUM(B18:M18) -> 1320000
A19: Total COGS | B19: =SUM(B15:B18) -> 100000 | C19: =SUM(C15:C18) -> 100000 | D19: =SUM(D15:D18) -> 100000 | E19: =SUM(E15:E18) -> 100000 | F19: =SUM(F15:F18) -> 100000 | G19: =SUM(G15:G18) -> 100000 | H19: =SUM(H15:H18) -> 150000 | I19: =SUM(I15:I18) -> 172500 | ... M19: =SUM(M15:M18) -> 300000 | N19: =SUM(B19:M19) -> 1905000
A21: Gross profit | B21: =B12-B19 -> 125000 | C21: =C12-C19 -> 425000 | D21: =D12-D19 -> 650000 | E21: =E12-E19 -> 950000 | F21: =F12-F19 -> 1175000 | G21: =G12-G19 -> 1325000 | H21: =H12-H19 -> 1650000 | I21: =I12-I19 -> 1852500 | ... M21: =M12-M19 -> 3300000 | N21: =SUM(B21:M21) -> 19095000
A22: Gross profit margin | B22: =IF(B12=0,"n.a.",B21/B12) -> 0.5556 | C22: =IF(C12=0,"n.a.",C21/C12) -> 0.8095 | D22: =IF(D12=0,"n.a.",D21/D12) -> 0.8667 | E22: =IF(E12=0,"n.a.",E21/E12) -> 0.9048 | F22: =IF(F12=0,"n.a.",F21/F12) -> 0.9216 | G22: =IF(G12=0,"n.a.",G21/G12) -> 0.9298 | H22: =IF(H12=0,"n.a.",H21/H12) -> 0.9167 | I22: =IF(I12=0,"n.a.",I21/I12) -> 0.9148 | ... N22: =IF(N12=0,"n.a.",N21/N12) -> 0.9093
A24: INDIRECT COSTS
A25: Rent | B25: 0 | C25: 0 | D25: 0 | E25: 0 | F25: 0 | G25: 0 | H25: 0 | I25: 0 | J25: 0 | K25: 0 | L25: 0 | M25: 0 | N25: =SUM(B25:M25) -> 0
A26: Administrative salaries | B26: 0 | C26: 0 | D26: 0 | E26: 0 | F26: 0 | G26: 0 | H26: 0 | I26: 0 | J26: 0 | K26: 0 | L26: 0 | M26: 0 | N26: =SUM(B26:M26) -> 0
A27: Utilities (Founder In-House: 0 IQD) | B27: 0 | C27: 0 | D27: 0 | E27: 0 | F27: 0 | G27: 0 | H27: 0 | I27: 0 | J27: 0 | K27: 0 | L27: 0 | M27: 0 | N27: =SUM(B27:M27) -> 0
A28: Targeted Meta Ads (Duhok) | B28: 150000 | C28: 150000 | D28: 150000 | E28: 150000 | F28: 150000 | G28: 150000 | H28: 37500 | I28: 37500 | J28: 45000 | K28: 45000 | L28: 60000 | M28: 60000 | N28: =SUM(B28:M28) -> 1185000
A29: Field Transport (Founder In-House: 0 IQD) | B29: 0 | C29: 0 | D29: 0 | E29: 0 | F29: 0 | G29: 0 | H29: 0 | I29: 0 | J29: 0 | K29: 0 | L29: 0 | M29: 0 | N29: =SUM(B29:M29) -> 0
A30: Repairs and maintenance | B30: 0 | C30: 0 | D30: 0 | E30: 0 | F30: 0 | G30: 0 | H30: 0 | I30: 0 | J30: 0 | K30: 0 | L30: 0 | M30: 0 | N30: =SUM(B30:M30) -> 0
A31: Cloudflare Pro, Redis & R2 Storage | B31: 72500 | C31: 72500 | D31: 72500 | E31: 72500 | F31: 72500 | G31: 72500 | H31: 72500 | I31: 72500 | J31: 72500 | K31: 72500 | L31: 72500 | M31: 72500 | N31: =SUM(B31:M31) -> 870000
A32: DCCI Commercial Trade Registration & Legal | B32: 87500 | C32: 87500 | D32: 87500 | E32: 87500 | F32: 87500 | G32: 87500 | H32: 0 | I32: 0 | J32: 0 | K32: 0 | L32: 0 | M32: 0 | N32: =SUM(B32:M32) -> 525000
A33: Depreciation (indirect assets) | B33: 0 | C33: 0 | D33: 0 | E33: 0 | F33: 0 | G33: 0 | H33: 0 | I33: 0 | J33: 0 | K33: 0 | L33: 0 | M33: 0 | N33: =SUM(B33:M33) -> 0
A34: API Compute Servers & WhatsApp Cloud API | B34: 140000 | C34: 140000 | D34: 140000 | E34: 140000 | F34: 140000 | G34: 140000 | H34: 124000 | I34: 128500 | J34: 133000 | K34: 139000 | L34: 160000 | M34: 167500 | N34: =SUM(B34:M34) -> 1692000
A35: Total indirect costs | B35: =SUM(B25:B34) -> 450000 | C35: =SUM(C25:C34) -> 450000 | D35: =SUM(D25:D34) -> 450000 | E35: =SUM(E25:E34) -> 450000 | F35: =SUM(F25:F34) -> 450000 | G35: =SUM(G25:G34) -> 450000 | H35: =SUM(H25:H34) -> 234000 | I35: =SUM(I25:I34) -> 238500 | ... M35: =SUM(M25:M34) -> 300000 | N35: =SUM(B35:M35) -> 4272000
A37: Operating profit / (loss) | B37: =B21-B35 -> -325000 | C37: =C21-C35 -> -25000 | D37: =D21-D35 -> 200000 | E37: =E21-E35 -> 500000 | F37: =F21-F35 -> 725000 | G37: =G21-G35 -> 875000 | H37: =H21-H35 -> 1416000 | I37: =I21-I35 -> 1614000 | ... M37: =M21-M35 -> 3000000 | N37: =SUM(B37:M37) -> 14823000
A39: OTHER INCOME AND EXPENSES
A40: GIZ Seed Grant Disbursement (Pilot Support) | B40: 550000 | C40: 550000 | D40: 550000 | E40: 550000 | F40: 550000 | G40: 550000 | H40: 0 | I40: 0 | J40: 0 | K40: 0 | L40: 0 | M40: 0 | N40: =SUM(B40:M40) -> 3300000
A41: Interest expense | B41: 0 | C41: 0 | D41: 0 | E41: 0 | F41: 0 | G41: 0 | H41: 0 | I41: 0 | J41: 0 | K41: 0 | L41: 0 | M41: 0 | N41: =SUM(B41:M41) -> 0
A42: Profit / (loss) before tax | B42: =B37+B40-B41 -> 225000 | C42: =C37+C40-C41 -> 525000 | D42: =D37+D40-D41 -> 750000 | E42: =E37+E40-E41 -> 1050000 | F42: =F37+F40-F41 -> 1275000 | G42: =G37+G40-G41 -> 1425000 | H42: =H37+H40-H41 -> 1416000 | I42: =I37+I40-I41 -> 1614000 | ... M42: =M37+M40-M41 -> 3000000 | N42: =SUM(B42:M42) -> 18123000
A43: Income tax expense | B43: 0 | C43: 0 | D43: 0 | E43: 0 | F43: 0 | G43: 0 | H43: 0 | I43: 0 | J43: 0 | K43: 0 | L43: 0 | M43: 0 | N43: =SUM(B43:M43) -> 0
A45: Net profit / (loss) | B45: =B42-B43 -> 225000 | C45: =C42-C43 -> 525000 | D45: =D42-D43 -> 750000 | E45: =E42-E43 -> 1050000 | F45: =F42-F43 -> 1275000 | G45: =G42-G43 -> 1425000 | H45: =H42-H43 -> 1416000 | I45: =I42-I43 -> 1614000 | ... M45: =M42-M43 -> 3000000 | N45: =SUM(B45:M45) -> 18123000
A46: Net profit margin | B46: =IF(B12=0,"n.a.",B45/B12) -> 1 | C46: =IF(C12=0,"n.a.",C45/C12) -> 1 | D46: =IF(D12=0,"n.a.",D45/D12) -> 1 | E46: =IF(E12=0,"n.a.",E45/E12) -> 1 | F46: =IF(F12=0,"n.a.",F45/F12) -> 1 | G46: =IF(G12=0,"n.a.",G45/G12) -> 1 | H46: =IF(H12=0,"n.a.",H45/H12) -> 0.7867 | I46: =IF(I12=0,"n.a.",I45/I12) -> 0.797 | ... N46: =IF(N12=0,"n.a.",N45/N12) -> 0.863
A48: COGS: enter the cost of items sold in the month. Inventory purchases may differ from COGS.
...
